https://api.f2pool.com/litecoin/dai5786
    conn = connection.create_connection(
  File "/usr/local/lib/python3.10/site-packages/urllib3/util/connection.py", line 95, in create_connection
    raise err
  File "/usr/local/lib/python3.10/site-packages/urllib3/util/connection.py", line 85, in create_connection
    sock.connect(sa)
TimeoutError: [Errno 110] Connection timed out

During handling of the above exception, another exception occurred:

Traceback (most recent call last):
  File "/usr/local/lib/python3.10/site-packages/urllib3/connectionpool.py", line 703, in urlopen
    httplib_response = self._make_request(
  File "/usr/local/lib/python3.10/site-packages/urllib3/connectionpool.py", line 398, in _make_request
    conn.request(method, url, **httplib_request_kw)
  File "/usr/local/lib/python3.10/site-packages/urllib3/connection.py", line 239, in request
    super(HTTPConnection, self).request(method, url, body=body, headers=headers)
  File "/usr/local/lib/python3.10/http/client.py", line 1282, in request
    self._send_request(method, url, body, headers, encode_chunked)
  File "/usr/local/lib/python3.10/http/client.py", line 1328, in _send_request
    self.endheaders(body, encode_chunked=encode_chunked)
  File "/usr/local/lib/python3.10/http/client.py", line 1277, in endheaders
    self._send_output(message_body, encode_chunked=encode_chunked)
  File "/usr/local/lib/python3.10/http/client.py", line 1037, in _send_output
    self.send(msg)
  File "/usr/local/lib/python3.10/http/client.py", line 975, in send
    self.connect()
  File "/usr/local/lib/python3.10/site-packages/urllib3/connection.py", line 205, in connect
    conn = self._new_conn()
  File "/usr/local/lib/python3.10/site-packages/urllib3/connection.py", line 179, in _new_conn
    raise ConnectTimeoutError(
urllib3.exceptions.ConnectTimeoutError: (<urllib3.connection.HTTPConnection object at 0x7f712873d930>, 'Connection to wxpusher.zjiecode.com timed out. (connect timeout=None)')

During handling of the above exception, another exception occurred:

Traceback (most recent call last):
  File "/usr/local/lib/python3.10/site-packages/requests/adapters.py", line 440, in send
    resp = conn.urlopen(
  File "/usr/local/lib/python3.10/site-packages/urllib3/connectionpool.py", line 785, in urlopen
    retries = retries.increment(
  File "/usr/local/lib/python3.10/site-packages/urllib3/util/retry.py", line 592, in increment
    raise MaxRetryError(_pool, url, error or ResponseError(cause))
urllib3.exceptions.MaxRetryError: HTTPConnectionPool(host='wxpusher.zjiecode.com', port=80): Max retries exceeded with url: /api/send/message (Caused by ConnectTimeoutError(<urllib3.connection.HTTPConnection object at 0x7f712873d930>, 'Connection to wxpusher.zjiecode.com timed out. (connect timeout=None)'))

During handling of the above exception, another exception occurred:

Traceback (most recent call last):
  File "/code/monitor.py", line 131, in main
    response = WxPusher.send_message(msg_text,
  File "/usr/local/lib/python3.10/site-packages/wxpusher/wxpusher.py", line 34, in send_message
    return requests.post(url, json=payload).json()
  File "/usr/local/lib/python3.10/site-packages/requests/api.py", line 117, in post
    return request('post', url, data=data, json=json, **kwargs)
  File "/usr/local/lib/python3.10/site-packages/requests/api.py", line 61, in request
    return session.request(method=method, url=url, **kwargs)
  File "/usr/local/lib/python3.10/site-packages/requests/sessions.py", line 529, in request
    resp = self.send(prep, **send_kwargs)
  File "/usr/local/lib/python3.10/site-packages/requests/sessions.py", line 645, in send
    r = adapter.send(request, **kwargs)
  File "/usr/local/lib/python3.10/site-packages/requests/adapters.py", line 507, in send
    raise ConnectTimeout(e, request=request)
requests.exceptions.ConnectTimeout: HTTPConnectionPool(host='wxpusher.zjiecode.com', port=80): Max retries exceeded with url: /api/send/message (Caused by ConnectTimeoutError(<urllib3.connection.HTTPConnection object at 0x7f712873d930>, 'Connection to wxpusher.zjiecode.com timed out. (connect timeout=None)'))

During handling of the above exception, another exception occurred:

Traceback (most recent call last):
  File "/code/monitor.py", line 152, in <module>
    main()
  File "/code/monitor.py", line 145, in main
    traceback.print_exc(e)
  File "/usr/local/lib/python3.10/traceback.py", line 179, in print_exc
    print_exception(*sys.exc_info(), limit=limit, file=file, chain=chain)
  File "/usr/local/lib/python3.10/traceback.py", line 119, in print_exception
    te = TracebackException(type(value), value, tb, limit=limit, compact=True)
  File "/usr/local/lib/python3.10/traceback.py", line 502, in __init__
    self.stack = StackSummary.extract(
  File "/usr/local/lib/python3.10/traceback.py", line 357, in extract
    if limit >= 0:
TypeError: '>=' not supported between instances of 'ConnectTimeout' and 'int'
